import numpy as np
import scipy.stats as si
import sympy as sy
from sympy.stats import Normal, cdf
from sympy import init_printing
init_printing()

import pandas as pd

Ratios_danone = pd.read_csv('C:/Users/botic/.cache/aria2/Ratios_danone.csv')

print(Ratios_danone)
                            date;30/06/2022
0                         share_price;53.26
1                   earning_per_share;0.169
2                 stockholders_Equity;18613
3  total_number_of_outstanding_share;639.36

import pandas as pd

df = pd.read_csv('import pandas as pd')
Traceback (most recent call last):

  File "C:\Users\botic\AppData\Local\Temp\ipykernel_23336\3814693594.py", line 1, in <module>
    df = pd.read_csv('import pandas as pd')

  File "C:\Users\botic\anaconda3\lib\site-packages\pandas\util\_decorators.py", line 311, in wrapper
    return func(*args, **kwargs)

  File "C:\Users\botic\anaconda3\lib\site-packages\pandas\io\parsers\readers.py", line 678, in read_csv
    return _read(filepath_or_buffer, kwds)

  File "C:\Users\botic\anaconda3\lib\site-packages\pandas\io\parsers\readers.py", line 575, in _read
    parser = TextFileReader(filepath_or_buffer, **kwds)

  File "C:\Users\botic\anaconda3\lib\site-packages\pandas\io\parsers\readers.py", line 932, in __init__
    self._engine = self._make_engine(f, self.engine)

  File "C:\Users\botic\anaconda3\lib\site-packages\pandas\io\parsers\readers.py", line 1216, in _make_engine
    self.handles = get_handle(  # type: ignore[call-overload]

  File "C:\Users\botic\anaconda3\lib\site-packages\pandas\io\common.py", line 786, in get_handle
    handle = open(

FileNotFoundError: [Errno 2] No such file or directory: 'import pandas as pd'


df = pd.read_csv('C:/Users/botic/.cache/aria2/Ratios_danone.csv', delimiter=';')

print(df)
                                date  30/06/2022
0                        share_price      53.260
1                  earning_per_share       0.169
2                stockholders_Equity   18613.000
3  total_number_of_outstanding_share     639.360

import pandas as pd

df = pd.read_csv('C:/Users/botic/.cache/aria2/Ratios_danone.csv', delimiter=';')

import pandas as pd

df = pd.read_csv('C:/Users/botic/.cache/aria2/Ratios_danone.csv', delimiter=';')

print(df)
                                date  30/06/2022
0                        share_price      53.260
1                  earning_per_share       0.169
2                stockholders_Equity   18613.000
3  total_number_of_outstanding_share     639.360

import pandas as pd

df = pd.read_csv('C:/Users/botic/.cache/aria2/Ratios_danone.csv', delimiter=';')

Share_price = df.loc[df['Data required'] == 'closing_price', '2022'].values[0]
Traceback (most recent call last):

  File "C:\Users\botic\anaconda3\lib\site-packages\pandas\core\indexes\base.py", line 3629, in get_loc
    return self._engine.get_loc(casted_key)

  File "pandas\_libs\index.pyx", line 136, in pandas._libs.index.IndexEngine.get_loc

  File "pandas\_libs\index.pyx", line 163, in pandas._libs.index.IndexEngine.get_loc

  File "pandas\_libs\hashtable_class_helper.pxi", line 5198, in pandas._libs.hashtable.PyObjectHashTable.get_item

  File "pandas\_libs\hashtable_class_helper.pxi", line 5206, in pandas._libs.hashtable.PyObjectHashTable.get_item

KeyError: 'Data required'


The above exception was the direct cause of the following exception:

Traceback (most recent call last):

  File "C:\Users\botic\AppData\Local\Temp\ipykernel_23336\2453380231.py", line 1, in <module>
    Share_price = df.loc[df['Data required'] == 'closing_price', '2022'].values[0]

  File "C:\Users\botic\anaconda3\lib\site-packages\pandas\core\frame.py", line 3505, in __getitem__
    indexer = self.columns.get_loc(key)

  File "C:\Users\botic\anaconda3\lib\site-packages\pandas\core\indexes\base.py", line 3631, in get_loc
    raise KeyError(key) from err

KeyError: 'Data required'


Share_price = df.loc[df['Data required'] == 'closing_price', '2022'].values[0]
Traceback (most recent call last):

  File "C:\Users\botic\anaconda3\lib\site-packages\pandas\core\indexes\base.py", line 3629, in get_loc
    return self._engine.get_loc(casted_key)

  File "pandas\_libs\index.pyx", line 136, in pandas._libs.index.IndexEngine.get_loc

  File "pandas\_libs\index.pyx", line 163, in pandas._libs.index.IndexEngine.get_loc

  File "pandas\_libs\hashtable_class_helper.pxi", line 5198, in pandas._libs.hashtable.PyObjectHashTable.get_item

  File "pandas\_libs\hashtable_class_helper.pxi", line 5206, in pandas._libs.hashtable.PyObjectHashTable.get_item

KeyError: 'Data required'


The above exception was the direct cause of the following exception:

Traceback (most recent call last):

  File "C:\Users\botic\AppData\Local\Temp\ipykernel_23336\2453380231.py", line 1, in <module>
    Share_price = df.loc[df['Data required'] == 'closing_price', '2022'].values[0]

  File "C:\Users\botic\anaconda3\lib\site-packages\pandas\core\frame.py", line 3505, in __getitem__
    indexer = self.columns.get_loc(key)

  File "C:\Users\botic\anaconda3\lib\site-packages\pandas\core\indexes\base.py", line 3631, in get_loc
    raise KeyError(key) from err

KeyError: 'Data required'


Share_price = df.loc[df['Data required'] == 'share_price', '2022'].values[0]
Traceback (most recent call last):

  File "C:\Users\botic\anaconda3\lib\site-packages\pandas\core\indexes\base.py", line 3629, in get_loc
    return self._engine.get_loc(casted_key)

  File "pandas\_libs\index.pyx", line 136, in pandas._libs.index.IndexEngine.get_loc

  File "pandas\_libs\index.pyx", line 163, in pandas._libs.index.IndexEngine.get_loc

  File "pandas\_libs\hashtable_class_helper.pxi", line 5198, in pandas._libs.hashtable.PyObjectHashTable.get_item

  File "pandas\_libs\hashtable_class_helper.pxi", line 5206, in pandas._libs.hashtable.PyObjectHashTable.get_item

KeyError: 'Data required'


The above exception was the direct cause of the following exception:

Traceback (most recent call last):

  File "C:\Users\botic\AppData\Local\Temp\ipykernel_23336\784444481.py", line 1, in <module>
    Share_price = df.loc[df['Data required'] == 'share_price', '2022'].values[0]

  File "C:\Users\botic\anaconda3\lib\site-packages\pandas\core\frame.py", line 3505, in __getitem__
    indexer = self.columns.get_loc(key)

  File "C:\Users\botic\anaconda3\lib\site-packages\pandas\core\indexes\base.py", line 3631, in get_loc
    raise KeyError(key) from err

KeyError: 'Data required'


share_price = df.loc[df['date'] == 'share_price', '30/06/2022'].values[0]

eps = df.loc[df['Data required'] == 'earning_per_share', '30/06/2022'].values[0]
Traceback (most recent call last):

  File "C:\Users\botic\anaconda3\lib\site-packages\pandas\core\indexes\base.py", line 3629, in get_loc
    return self._engine.get_loc(casted_key)

  File "pandas\_libs\index.pyx", line 136, in pandas._libs.index.IndexEngine.get_loc

  File "pandas\_libs\index.pyx", line 163, in pandas._libs.index.IndexEngine.get_loc

  File "pandas\_libs\hashtable_class_helper.pxi", line 5198, in pandas._libs.hashtable.PyObjectHashTable.get_item

  File "pandas\_libs\hashtable_class_helper.pxi", line 5206, in pandas._libs.hashtable.PyObjectHashTable.get_item

KeyError: 'Data required'


The above exception was the direct cause of the following exception:

Traceback (most recent call last):

  File "C:\Users\botic\AppData\Local\Temp\ipykernel_23336\1061635618.py", line 1, in <module>
    eps = df.loc[df['Data required'] == 'earning_per_share', '30/06/2022'].values[0]

  File "C:\Users\botic\anaconda3\lib\site-packages\pandas\core\frame.py", line 3505, in __getitem__
    indexer = self.columns.get_loc(key)

  File "C:\Users\botic\anaconda3\lib\site-packages\pandas\core\indexes\base.py", line 3631, in get_loc
    raise KeyError(key) from err

KeyError: 'Data required'


share_price = df.loc[df['date'] == 'share_price', '30/06/2022'].values[0]

eps = df.loc[df['date'] == 'earning_per_share', '30/06/2022'].values[0]

book_value = df.loc[df['date'] == 'stockholders_equity', '30/06/2022'].values[0] / df.loc[df['date'] == 'total_number_of outstanding_share', '30/06/2022'].values[0]
Traceback (most recent call last):

  File "C:\Users\botic\AppData\Local\Temp\ipykernel_23336\3002581584.py", line 1, in <module>
    book_value = df.loc[df['date'] == 'stockholders_equity', '30/06/2022'].values[0] / df.loc[df['date'] == 'total_number_of outstanding_share', '30/06/2022'].values[0]

IndexError: index 0 is out of bounds for axis 0 with size 0


book_value = df.loc[df['date'] == 'stockholders_equity', '30/06/2022'].values[0]
Traceback (most recent call last):

  File "C:\Users\botic\AppData\Local\Temp\ipykernel_23336\2461994777.py", line 1, in <module>
    book_value = df.loc[df['date'] == 'stockholders_equity', '30/06/2022'].values[0]

IndexError: index 0 is out of bounds for axis 0 with size 0


book_value = df.loc[df['date'] == 'stockholders_Equity', '30/06/2022'].values[0]

del(book_value)

book_value = df.loc[df['date'] == 'stockholders_Equity', '30/06/2022'].values[0] / df.loc[df['date'] == 'total_number_of outstanding_share', '30/06/2022'].values[0]
Traceback (most recent call last):

  File "C:\Users\botic\AppData\Local\Temp\ipykernel_23336\1020039237.py", line 1, in <module>
    book_value = df.loc[df['date'] == 'stockholders_Equity', '30/06/2022'].values[0] / df.loc[df['date'] == 'total_number_of outstanding_share', '30/06/2022'].values[0]

IndexError: index 0 is out of bounds for axis 0 with size 0


stockholders_equity = df.loc[df['date'] == 'stockholders_Equity', '30/06/2022'].values[0]

total_number_of outstanding_share = df.loc[df['date'] == 'total_number_of outstanding_share', '30/06/2022'].values[0]
  File "C:\Users\botic\AppData\Local\Temp\ipykernel_23336\2530626757.py", line 1
    total_number_of outstanding_share = df.loc[df['date'] == 'total_number_of outstanding_share', '30/06/2022'].values[0]
                    ^
SyntaxError: invalid syntax


total_number_of_outstanding_share = df.loc[df['date'] == 'total_number_of outstanding_share', '30/06/2022'].values[0]
Traceback (most recent call last):

  File "C:\Users\botic\AppData\Local\Temp\ipykernel_23336\1533757040.py", line 1, in <module>
    total_number_of_outstanding_share = df.loc[df['date'] == 'total_number_of outstanding_share', '30/06/2022'].values[0]

IndexError: index 0 is out of bounds for axis 0 with size 0


total_number_of_outstanding_share = df.loc[df['date'] == 'total_number_of_outstanding_share', '30/06/2022'].values[0]

book_value = stockholders_equity / total_number_of_outstanding_share

pe_ratio = share_price / eps

pb_ratio = share_price / book_value

print(f"P/E Ratio: {pe_ratio}")
P/E Ratio: 315.1479289940828

print(f"P/B Ratio: {pb_ratio}")
P/B Ratio: 1.8294908719712029

print(f"BV: {book_value}")
BV: 29.111924424424423
